Traceback (most recent call last):
  File "/usr/share/miniconda/lib/python3.10/site-packages/jupyter_cache/executors/utils.py", line 51, in single_nb_execution
    executenb(
  File "/usr/share/miniconda/lib/python3.10/site-packages/nbclient/client.py", line 1204, in execute
    return NotebookClient(nb=nb, resources=resources, km=km, **kwargs).execute()
  File "/usr/share/miniconda/lib/python3.10/site-packages/nbclient/util.py", line 84, in wrapped
    return just_run(coro(*args, **kwargs))
  File "/usr/share/miniconda/lib/python3.10/site-packages/nbclient/util.py", line 62, in just_run
    return loop.run_until_complete(coro)
  File "/usr/share/miniconda/lib/python3.10/asyncio/base_events.py", line 649, in run_until_complete
    return future.result()
  File "/usr/share/miniconda/lib/python3.10/site-packages/nbclient/client.py", line 663, in async_execute
    await self.async_execute_cell(
  File "/usr/share/miniconda/lib/python3.10/site-packages/nbclient/client.py", line 965, in async_execute_cell
    await self._check_raise_for_error(cell, cell_index, exec_reply)
  File "/usr/share/miniconda/lib/python3.10/site-packages/nbclient/client.py", line 862, in _check_raise_for_error
    raise CellExecutionError.from_cell_and_msg(cell, exec_reply_content)
nbclient.exceptions.CellExecutionError: An error occurred while executing the following cell:
------------------
for row in filtered_products:
    if row['productSubGroupDescription'] == 'FLC':
        subprocess.check_output('crds bestrefs --files {}_flc.fits --sync-references=1 --update-bestrefs'.format(row['obs_id']), \
                                shell=True, stderr=subprocess.DEVNULL)

------------------

[0;31m---------------------------------------------------------------------------[0m
[0;31mCalledProcessError[0m                        Traceback (most recent call last)
Cell [0;32mIn[6], line 3[0m
[1;32m      1[0m [38;5;28;01mfor[39;00m row [38;5;129;01min[39;00m filtered_products:
[1;32m      2[0m     [38;5;28;01mif[39;00m row[[38;5;124m'[39m[38;5;124mproductSubGroupDescription[39m[38;5;124m'[39m] [38;5;241m==[39m [38;5;124m'[39m[38;5;124mFLC[39m[38;5;124m'[39m:
[0;32m----> 3[0m         [43msubprocess[49m[38;5;241;43m.[39;49m[43mcheck_output[49m[43m([49m[38;5;124;43m'[39;49m[38;5;124;43mcrds bestrefs --files [39;49m[38;5;132;43;01m{}[39;49;00m[38;5;124;43m_flc.fits --sync-references=1 --update-bestrefs[39;49m[38;5;124;43m'[39;49m[38;5;241;43m.[39;49m[43mformat[49m[43m([49m[43mrow[49m[43m[[49m[38;5;124;43m'[39;49m[38;5;124;43mobs_id[39;49m[38;5;124;43m'[39;49m[43m][49m[43m)[49m[43m,[49m[43m [49m[43m\[49m
[1;32m      4[0m [43m                                [49m[43mshell[49m[38;5;241;43m=[39;49m[38;5;28;43;01mTrue[39;49;00m[43m,[49m[43m [49m[43mstderr[49m[38;5;241;43m=[39;49m[43msubprocess[49m[38;5;241;43m.[39;49m[43mDEVNULL[49m[43m)[49m

File [0;32m/usr/share/miniconda/lib/python3.10/subprocess.py:421[0m, in [0;36mcheck_output[0;34m(timeout, *popenargs, **kwargs)[0m
[1;32m    418[0m         empty [38;5;241m=[39m [38;5;124mb[39m[38;5;124m'[39m[38;5;124m'[39m
[1;32m    419[0m     kwargs[[38;5;124m'[39m[38;5;124minput[39m[38;5;124m'[39m] [38;5;241m=[39m empty
[0;32m--> 421[0m [38;5;28;01mreturn[39;00m [43mrun[49m[43m([49m[38;5;241;43m*[39;49m[43mpopenargs[49m[43m,[49m[43m [49m[43mstdout[49m[38;5;241;43m=[39;49m[43mPIPE[49m[43m,[49m[43m [49m[43mtimeout[49m[38;5;241;43m=[39;49m[43mtimeout[49m[43m,[49m[43m [49m[43mcheck[49m[38;5;241;43m=[39;49m[38;5;28;43;01mTrue[39;49;00m[43m,[49m
[1;32m    422[0m [43m           [49m[38;5;241;43m*[39;49m[38;5;241;43m*[39;49m[43mkwargs[49m[43m)[49m[38;5;241m.[39mstdout

File [0;32m/usr/share/miniconda/lib/python3.10/subprocess.py:526[0m, in [0;36mrun[0;34m(input, capture_output, timeout, check, *popenargs, **kwargs)[0m
[1;32m    524[0m     retcode [38;5;241m=[39m process[38;5;241m.[39mpoll()
[1;32m    525[0m     [38;5;28;01mif[39;00m check [38;5;129;01mand[39;00m retcode:
[0;32m--> 526[0m         [38;5;28;01mraise[39;00m CalledProcessError(retcode, process[38;5;241m.[39margs,
[1;32m    527[0m                                  output[38;5;241m=[39mstdout, stderr[38;5;241m=[39mstderr)
[1;32m    528[0m [38;5;28;01mreturn[39;00m CompletedProcess(process[38;5;241m.[39margs, retcode, stdout, stderr)

[0;31mCalledProcessError[0m: Command 'crds bestrefs --files hst_14689_07_wfc3_uvis_f814w_id7307xf_flc.fits --sync-references=1 --update-bestrefs' returned non-zero exit status 127.
CalledProcessError: Command 'crds bestrefs --files hst_14689_07_wfc3_uvis_f814w_id7307xf_flc.fits --sync-references=1 --update-bestrefs' returned non-zero exit status 127.

